Workbook
Name AUTRE: Paramétrage!$L$3:$L$18
Name CEI: Paramétrage!$P$21:$P$36
Name CODING: Paramétrage!$S$21:$S$36
Name Coeff_Fiscal: 'NDF A IMPRIMER Détail'!$I$13
Name COMEVE: Paramétrage!$P$3:$P$8
Name CORP: Paramétrage!$L$21:$L$36
Name DIGITAL: Paramétrage!$N$21:$N$36
Name Hotel: Paramétrage!$C$16
Name IT: Paramétrage!$M$21:$M$36
Name JPO: Paramétrage!$N$3:$N$8
Name Limit_dej: Paramétrage!$C$14
Name Limit_Diner: Paramétrage!$C$15
Name Puissance_Fiscale: 'NDF A IMPRIMER Détail'!$I$11
Name RE: Paramétrage!$Q$21:$Q$36
Name RI: Paramétrage!$O$21:$O$36
Name SALON: Paramétrage!$O$3:$O$8
Name SAMSUNG: Paramétrage!$T$21:$T$36
Name SEM: Paramétrage!$M$3:$M$8
Name WAC: Paramétrage!$R$21:$R$36
Name WCS: Paramétrage!$U$21:$U$36

Sheet Mode d'emploi
A1: DAFIONIS

Sheet NDF A IMPRIMER Détail
A1: Maquette de Note de Frais
A3: Prénom : | B3: Nicolas | H3: Période du | I3: =MIN(NDF[Date JJ/MM/AAAA]) -> 46308
A4: NOM : | B4: TORO | H4: Au | I4: =MAX(NDF[Date JJ/MM/AAAA]) -> 46308
A5: Fonction : | B5: Etudiant
A6: Ecole/Prog/Dépt : | B6: EPITECH IT | D6: =IF(B6="","",VLOOKUP(B6,Paramétrage!$E$2:$F$12,2,FALSE)) -> IT
A7: Ville : | B7: PARIS et RP | H7: Disposez vous d'une avance sur frais ? | I7: Non
C9: Motif : | D9: Infrastructure et nom de domaine pour l'Epitech Innovative Project (EIP) "Ascension"
H11: Puissance Fiscale :
H13: =CONCATENATE("Selon le ",Paramétrage!A2," votre cofficient de remboursement sera de :") -> Selon le Barème Fiscal automobile 2020 votre cofficient de remboursement sera de : | I13: =IF(ISNA(INDEX(Paramétrage!C5:C9,MATCH('NDF A IMPRIMER Détail'!I11,Paramétrage!D5:D9,0),0)),Paramétrage!$C$10,INDEX(Paramétrage!C5:C9,MATCH('NDF A IMPRIMER Détail'!I11,Paramétrage!D5:D9,0),0)) -> 0.601
K14: Montant de la NDF
E15: à remplir (impérativement) | H15: A remplir Obligatoirement pour les Repas | K15: =SUBTOTAL(9,NDF[Remboursement Calculé]) -> 34.18
A16: N° du ticket | B16: Ecole/Prog/Dépt | C16: Ville | D16: Date JJ/MM/AAAA | E16: Evénement | F16: Type de dépense | G16: Total | H16: Déjeuner/Dîner | I16: Nb de pers | J16: Commentaire | K16: Remboursement Calculé | L16: Numéro de compte | M16: Libellé de compte | N16: Menu déroulant ville | O16: Colonne1 | P16: Section Ana | Q16: Montant NDF | R16: Menu déroulant | S16: Colonne2
A17: 1 | D17: 46308 | E17: Autre | F17: Achats Informatiques | G17: 5.99 | J17: Nom de domaine (OVH) | K17: =IF(AND(NDF[[#This Row],[Type de dépense]]="Repas",NDF[[#This Row],[Déjeuner/Dîner]]="Dîner",Limit_Diner=0),NDF[[#This Row],[Total]],IF(AND(NDF[[#This Row],[Type de dépense]]="Repas",NDF[[#This Row],[Déjeuner/Dîner]]="Déjeuner",Limit_dej=0),NDF[[#This Row],[Total]],IF(AND(NDF[[#This Row],[Type de dépense]]="Hébergement",Hotel=0),NDF[[#This Row],[Total]],IF(AND(NDF[[#This Row],[Type de dépense]]="Hébergement",NDF[[#This Row],[Total]]>Hotel),Hotel,IF(AND(NDF[[#This Row],[Type de dépense]]="Véhicule Personnel (trajet en Km Ecole/Salon)",Puissance_Fiscale=""),"",IF(AND(NDF[[#This Row],[Type de dépense]]="Repas",NDF[[#This Row],[Déjeuner/Dîner]]<>0,NDF[[#This Row],[Nb de pers]]=""),"",IF(AND(NDF[[#This Row],[Type de dépense]]="Repas",NDF[[#This Row],[Déjeuner/Dîner]]="Déjeuner"),IF(NDF[[#This Row],[Total]]/NDF[[#This Row],[Nb de pers]]<(Limit_dej+0.01),NDF[[#This Row],[Total]],NDF[[#This Row],[Nb de pers]]*Limit_dej),IF(AND(NDF[[#This Row],[Type de dépense]]="Repas",NDF[[#This Row],[Déjeuner/Dîner]]="Dîner"),IF(NDF[[#This Row],[Total]]/NDF[[#This Row],[Nb de pers]]<Limit_Diner+0.01,NDF[[#This Row],[Total]],NDF[[#This Row],[Nb de pers]]*Limit_Diner),IF(NDF[[#This Row],[Type de dépense]]="Véhicule Personnel (trajet en Km Ecole/Salon)",NDF[[#This Row],[Total]]*Coeff_Fiscal,IF(AND(NDF[[#This Row],[Type de dépense]]="Repas",OR(NDF[[#This Row],[Déjeuner/Dîner]]="",NDF[[#This Row],[Nb de pers]]="")),"",NDF[[#This Row],[Total]])))))))))) -> 5.99 | L17: =IF(NDF[[#This Row],[Remboursement Calculé]]="","en attente",IF(ISNA(INDEX(Mapping_Comptable[Libellé comptable],MATCH(CONCATENATE(NDF[[#This Row],[Evénement]],"/",NDF[[#This Row],[Type de dépense]]),Mapping_Comptable[Column1],0),0)),"en attente",IF(AND(NDF[[#This Row],[Type de dépense]]="Repas",OR(NDF[[#This Row],[Déjeuner/Dîner]]="",NDF[[#This Row],[Nb de pers]]="")),"PB REPAS",INDEX(Mapping_Comptable[Compte Comptable],MATCH(CONCATENATE(NDF[[#This Row],[Evénement]],"/",NDF[[#This Row],[Type de dépense]]),Mapping_Comptable[Column1],0),0)))) -> 46760643 | M17: =IF(NDF[[#This Row],[Remboursement Calculé]]="","en attente",IF(ISNA(INDEX(Mapping_Comptable[Libellé comptable],MATCH(CONCATENATE(NDF[[#This Row],[Evénement]],"/",NDF[[#This Row],[Type de dépense]]),Mapping_Comptable[Column1],0),0)),"en attente",IF(AND(NDF[[#This Row],[Type de dépense]]="Repas",OR(NDF[[#This Row],[Déjeuner/Dîner]]="",NDF[[#This Row],[Nb de pers]]="")),"",INDEX(Mapping_Comptable[Libellé comptable],MATCH(CONCATENATE(NDF[[#This Row],[Evénement]],"/",NDF[[#This Row],[Type de dépense]]),Mapping_Comptable[Column1],0),0)))) -> FOURNITURES DIVERS INFORMATIQUE | N17: =IF(B17="","",VLOOKUP(B17,Paramétrage!$E$2:$F$12,2,FALSE)) | O17: =IF(AND(NDF[[#This Row],[Ecole/Prog/Dépt]]="",NDF[[#This Row],[Ville]]=""),$B$6&$B$7,IF(AND(NDF[[#This Row],[Ecole/Prog/Dépt]]="",NDF[[#This Row],[Ville]]<>""),$B$6&NDF[[#This Row],[Ville]],IF(AND(NDF[[#This Row],[Ecole/Prog/Dépt]]<>"",NDF[[#This Row],[Ville]]=""),NDF[[#This Row],[Ecole/Prog/Dépt]]&$B$7,IF(AND(NDF[[#This Row],[Ecole/Prog/Dépt]]<>"",NDF[[#This Row],[Ville]]<>""),NDF[[#This Row],[Ecole/Prog/Dépt]]&NDF[[#This Row],[Ville]],"")))) -> EPITECH ITPARIS et RP | P17: =VLOOKUP(NDF[[#This Row],[Colonne1]],Paramétrage!$L$73:$M$223,2,FALSE) -> 0068 - IT PARIS | Q17: Montant NDF | R17: =HLOOKUP(NDF[[#This Row],[Evénement]],Paramétrage!$L$1:$P$2,2,0) -> AUTRE | S17: =IF(AND(NDF[[#This Row],[Remboursement Calculé]]="",NDF[[#This Row],[Libellé de compte]]="en attente",NDF[[#This Row],[Type de dépense]]="Véhicule Personnel (trajet en Km Ecole/Salon)"),"Trajet ! Veuillez renseigner la puissance Fiscale de votre véhicule",IF(AND(NDF[[#This Row],[Evénement]]="Autre",NDF[[#This Row],[Type de dépense]]="Autre"),"En attente affectation par le comptable, renseigner un commentaire",IF(AND(NDF[[#This Row],[Remboursement Calculé]]>0,NDF[[#This Row],[Libellé de compte]]="en attente"),"Attention Evénement et Type de Dépense INCOMPATIBLES",IF(AND(NDF[[#This Row],[Type de dépense]]="Repas",OR(NDF[[#This Row],[Déjeuner/Dîner]]="",NDF[[#This Row],[Nb de pers]]="")),"Attention type de Dépense 'Repas' renseignez aussi le Type de Repas et/ou le nb de pers",IF(AND($B$7="",NDF[[#This Row],[Ville]]=""),"Ville non renseignée",IF(AND($B$6="",NDF[[#This Row],[Ecole/Prog/Dépt]]=""),"Ecole/Prog/Dépt non renseignés",""))))))
A18: 2 | D18: 46308 | E18: Autre | F18: Achats Informatiques | G18: 28.19 | J18: VPS (VPS-4 2027 OVH) | K18: =IF(AND(NDF[[#This Row],[Type de dépense]]="Repas",NDF[[#This Row],[Déjeuner/Dîner]]="Dîner",Limit_Diner=0),NDF[[#This Row],[Total]],IF(AND(NDF[[#This Row],[Type de dépense]]="Repas",NDF[[#This Row],[Déjeuner/Dîner]]="Déjeuner",Limit_dej=0),NDF[[#This Row],[Total]],IF(AND(NDF[[#This Row],[Type de dépense]]="Hébergement",Hotel=0),NDF[[#This Row],[Total]],IF(AND(NDF[[#This Row],[Type de dépense]]="Hébergement",NDF[[#This Row],[Total]]>Hotel),Hotel,IF(AND(NDF[[#This Row],[Type de dépense]]="Véhicule Personnel (trajet en Km Ecole/Salon)",Puissance_Fiscale=""),"",IF(AND(NDF[[#This Row],[Type de dépense]]="Repas",NDF[[#This Row],[Déjeuner/Dîner]]<>0,NDF[[#This Row],[Nb de pers]]=""),"",IF(AND(NDF[[#This Row],[Type de dépense]]="Repas",NDF[[#This Row],[Déjeuner/Dîner]]="Déjeuner"),IF(NDF[[#This Row],[Total]]/NDF[[#This Row],[Nb de pers]]<(Limit_dej+0.01),NDF[[#This Row],[Total]],NDF[[#This Row],[Nb de pers]]*Limit_dej),IF(AND(NDF[[#This Row],[Type de dépense]]="Repas",NDF[[#This Row],[Déjeuner/Dîner]]="Dîner"),IF(NDF[[#This Row],[Total]]/NDF[[#This Row],[Nb de pers]]<Limit_Diner+0.01,NDF[[#This Row],[Total]],NDF[[#This Row],[Nb de pers]]*Limit_Diner),IF(NDF[[#This Row],[Type de dépense]]="Véhicule Personnel (trajet en Km Ecole/Salon)",NDF[[#This Row],[Total]]*Coeff_Fiscal,IF(AND(NDF[[#This Row],[Type de dépense]]="Repas",OR(NDF[[#This Row],[Déjeuner/Dîner]]="",NDF[[#This Row],[Nb de pers]]="")),"",NDF[[#This Row],[Total]])))))))))) -> 28.19 | L18: =IF(NDF[[#This Row],[Remboursement Calculé]]="","",IF(ISNA(INDEX(Mapping_Comptable[Libellé comptable],MATCH(CONCATENATE(NDF[[#This Row],[Evénement]],"/",NDF[[#This Row],[Type de dépense]]),Mapping_Comptable[Column1],0),0)),"en attente",IF(AND(NDF[[#This Row],[Type de dépense]]="Repas",OR(NDF[[#This Row],[Déjeuner/Dîner]]="",NDF[[#This Row],[Nb de pers]]="")),"",INDEX(Mapping_Comptable[Compte Comptable],MATCH(CONCATENATE(NDF[[#This Row],[Evénement]],"/",NDF[[#This Row],[Type de dépense]]),Mapping_Comptable[Column1],0),0)))) -> 46760643 | M18: =IF(NDF[[#This Row],[Remboursement Calculé]]="","en attente",IF(ISNA(INDEX(Mapping_Comptable[Libellé comptable],MATCH(CONCATENATE(NDF[[#This Row],[Evénement]],"/",NDF[[#This Row],[Type de dépense]]),Mapping_Comptable[Column1],0),0)),"en attente",IF(AND(NDF[[#This Row],[Type de dépense]]="Repas",OR(NDF[[#This Row],[Déjeuner/Dîner]]="",NDF[[#This Row],[Nb de pers]]="")),"",INDEX(Mapping_Comptable[Libellé comptable],MATCH(CONCATENATE(NDF[[#This Row],[Evénement]],"/",NDF[[#This Row],[Type de dépense]]),Mapping_Comptable[Column1],0),0)))) -> FOURNITURES DIVERS INFORMATIQUE | N18: =IF(B18="","",VLOOKUP(B18,Paramétrage!$E$2:$F$12,2,FALSE)) | O18: =IF(AND(NDF[[#This Row],[Ecole/Prog/Dépt]]="",NDF[[#This Row],[Ville]]=""),$B$6&$B$7,IF(AND(NDF[[#This Row],[Ecole/Prog/Dépt]]="",NDF[[#This Row],[Ville]]<>""),$B$6&NDF[[#This Row],[Ville]],IF(AND(NDF[[#This Row],[Ecole/Prog/Dépt]]<>"",NDF[[#This Row],[Ville]]=""),NDF[[#This Row],[Ecole/Prog/Dépt]]&$B$7,IF(AND(NDF[[#This Row],[Ecole/Prog/Dépt]]<>"",NDF[[#This Row],[Ville]]<>""),NDF[[#This Row],[Ecole/Prog/Dépt]]&NDF[[#This Row],[Ville]],"")))) -> EPITECH ITPARIS et RP | P18: =VLOOKUP(NDF[[#This Row],[Colonne1]],Paramétrage!$L$73:$M$223,2,FALSE) -> 0068 - IT PARIS | Q18: Montant NDF | R18: =HLOOKUP(NDF[[#This Row],[Evénement]],Paramétrage!$L$1:$P$2,2,0) -> AUTRE | S18: =IF(AND(NDF[[#This Row],[Remboursement Calculé]]="",NDF[[#This Row],[Libellé de compte]]="en attente",NDF[[#This Row],[Type de dépense]]="Véhicule Personnel (trajet en Km Ecole/Salon)"),"Trajet ! Veuillez renseigner la puissance Fiscale de votre véhicule",IF(AND(NDF[[#This Row],[Evénement]]="Autre",NDF[[#This Row],[Type de dépense]]="Autre"),"En attente affectation par le comptable, renseigner un commentaire",IF(AND(NDF[[#This Row],[Remboursement Calculé]]>0,NDF[[#This Row],[Libellé de compte]]="en attente"),"Attention Evénement et Type de Dépense INCOMPATIBLES",IF(AND(NDF[[#This Row],[Type de dépense]]="Repas",OR(NDF[[#This Row],[Déjeuner/Dîner]]="",NDF[[#This Row],[Nb de pers]]="")),"Attention type de Dépense 'Repas' renseignez aussi le Type de Repas et/ou le nb de pers",IF(AND($B$7="",NDF[[#This Row],[Ville]]=""),"Ville non renseignée",IF(AND($B$6="",NDF[[#This Row],[Ecole/Prog/Dépt]]=""),"Ecole/Prog/Dépt non renseignés",""))))))
A19: 3 | K19: =IF(AND(NDF[[#This Row],[Type de dépense]]="Repas",NDF[[#This Row],[Déjeuner/Dîner]]="Dîner",Limit_Diner=0),NDF[[#This Row],[Total]],IF(AND(NDF[[#This Row],[Type de dépense]]="Repas",NDF[[#This Row],[Déjeuner/Dîner]]="Déjeuner",Limit_dej=0),NDF[[#This Row],[Total]],IF(AND(NDF[[#This Row],[Type de dépense]]="Hébergement",Hotel=0),NDF[[#This Row],[Total]],IF(AND(NDF[[#This Row],[Type de dépense]]="Hébergement",NDF[[#This Row],[Total]]>Hotel),Hotel,IF(AND(NDF[[#This Row],[Type de dépense]]="Véhicule Personnel (trajet en Km Ecole/Salon)",Puissance_Fiscale=""),"",IF(AND(NDF[[#This Row],[Type de dépense]]="Repas",NDF[[#This Row],[Déjeuner/Dîner]]<>0,NDF[[#This Row],[Nb de pers]]=""),"",IF(AND(NDF[[#This Row],[Type de dépense]]="Repas",NDF[[#This Row],[Déjeuner/Dîner]]="Déjeuner"),IF(NDF[[#This Row],[Total]]/NDF[[#This Row],[Nb de pers]]<(Limit_dej+0.01),NDF[[#This Row],[Total]],NDF[[#This Row],[Nb de pers]]*Limit_dej),IF(AND(NDF[[#This Row],[Type de dépense]]="Repas",NDF[[#This Row],[Déjeuner/Dîner]]="Dîner"),IF(NDF[[#This Row],[Total]]/NDF[[#This Row],[Nb de pers]]<Limit_Diner+0.01,NDF[[#This Row],[Total]],NDF[[#This Row],[Nb de pers]]*Limit_Diner),IF(NDF[[#This Row],[Type de dépense]]="Véhicule Personnel (trajet en Km Ecole/Salon)",NDF[[#This Row],[Total]]*Coeff_Fiscal,IF(AND(NDF[[#This Row],[Type de dépense]]="Repas",OR(NDF[[#This Row],[Déjeuner/Dîner]]="",NDF[[#This Row],[Nb de pers]]="")),"",NDF[[#This Row],[Total]])))))))))) -> 0 | L19: =IF(NDF[[#This Row],[Remboursement Calculé]]="","",IF(ISNA(INDEX(Mapping_Comptable[Libellé comptable],MATCH(CONCATENATE(NDF[[#This Row],[Evénement]],"/",NDF[[#This Row],[Type de dépense]]),Mapping_Comptable[Column1],0),0)),"en attente",IF(AND(NDF[[#This Row],[Type de dépense]]="Repas",OR(NDF[[#This Row],[Déjeuner/Dîner]]="",NDF[[#This Row],[Nb de pers]]="")),"",INDEX(Mapping_Comptable[Compte Comptable],MATCH(CONCATENATE(NDF[[#This Row],[Evénement]],"/",NDF[[#This Row],[Type de dépense]]),Mapping_Comptable[Column1],0),0)))) -> en attente | M19: =IF(NDF[[#This Row],[Remboursement Calculé]]="","en attente",IF(ISNA(INDEX(Mapping_Comptable[Libellé comptable],MATCH(CONCATENATE(NDF[[#This Row],[Evénement]],"/",NDF[[#This Row],[Type de dépense]]),Mapping_Comptable[Column1],0),0)),"en attente",IF(AND(NDF[[#This Row],[Type de dépense]]="Repas",OR(NDF[[#This Row],[Déjeuner/Dîner]]="",NDF[[#This Row],[Nb de pers]]="")),"",INDEX(Mapping_Comptable[Libellé comptable],MATCH(CONCATENATE(NDF[[#This Row],[Evénement]],"/",NDF[[#This Row],[Type de dépense]]),Mapping_Comptable[Column1],0),0)))) -> en attente | N19: =IF(B19="","",VLOOKUP(B19,Paramétrage!$E$2:$F$12,2,FALSE)) | O19: =IF(AND(NDF[[#This Row],[Ecole/Prog/Dépt]]="",NDF[[#This Row],[Ville]]=""),$B$6&$B$7,IF(AND(NDF[[#This Row],[Ecole/Prog/Dépt]]="",NDF[[#This Row],[Ville]]<>""),$B$6&NDF[[#This Row],[Ville]],IF(AND(NDF[[#This Row],[Ecole/Prog/Dépt]]<>"",NDF[[#This Row],[Ville]]=""),NDF[[#This Row],[Ecole/Prog/Dépt]]&$B$7,IF(AND(NDF[[#This Row],[Ecole/Prog/Dépt]]<>"",NDF[[#This Row],[Ville]]<>""),NDF[[#This Row],[Ecole/Prog/Dépt]]&NDF[[#This Row],[Ville]],"")))) -> EPITECH ITPARIS et RP | P19: =VLOOKUP(NDF[[#This Row],[Colonne1]],Paramétrage!$L$73:$M$223,2,FALSE) -> 0068 - IT PARIS | Q19: Montant NDF | R19: =HLOOKUP(NDF[[#This Row],[Evénement]],Paramétrage!$L$1:$P$2,2,0) -> #N/A | S19: =IF(AND(NDF[[#This Row],[Remboursement Calculé]]="",NDF[[#This Row],[Libellé de compte]]="en attente",NDF[[#This Row],[Type de dépense]]="Véhicule Personnel (trajet en Km Ecole/Salon)"),"Trajet ! Veuillez renseigner la puissance Fiscale de votre véhicule",IF(AND(NDF[[#This Row],[Evénement]]="Autre",NDF[[#This Row],[Type de dépense]]="Autre"),"En attente affectation par le comptable, renseigner un commentaire",IF(AND(NDF[[#This Row],[Remboursement Calculé]]>0,NDF[[#This Row],[Libellé de compte]]="en attente"),"Attention Evénement et Type de Dépense INCOMPATIBLES",IF(AND(NDF[[#This Row],[Type de dépense]]="Repas",OR(NDF[[#This Row],[Déjeuner/Dîner]]="",NDF[[#This Row],[Nb de pers]]="")),"Attention type de Dépense 'Repas' renseignez aussi le Type de Repas et/ou le nb de pers",IF(AND($B$7="",NDF[[#This Row],[Ville]]=""),"Ville non renseignée",IF(AND($B$6="",NDF[[#This Row],[Ecole/Prog/Dépt]]=""),"Ecole/Prog/Dépt non renseignés",""))))))
A20: 4 | K20: =IF(AND(NDF[[#This Row],[Type de dépense]]="Repas",NDF[[#This Row],[Déjeuner/Dîner]]="Dîner",Limit_Diner=0),NDF[[#This Row],[Total]],IF(AND(NDF[[#This Row],[Type de dépense]]="Repas",NDF[[#This Row],[Déjeuner/Dîner]]="Déjeuner",Limit_dej=0),NDF[[#This Row],[Total]],IF(AND(NDF[[#This Row],[Type de dépense]]="Hébergement",Hotel=0),NDF[[#This Row],[Total]],IF(AND(NDF[[#This Row],[Type de dépense]]="Hébergement",NDF[[#This Row],[Total]]>Hotel),Hotel,IF(AND(NDF[[#This Row],[Type de dépense]]="Véhicule Personnel (trajet en Km Ecole/Salon)",Puissance_Fiscale=""),"",IF(AND(NDF[[#This Row],[Type de dépense]]="Repas",NDF[[#This Row],[Déjeuner/Dîner]]<>0,NDF[[#This Row],[Nb de pers]]=""),"",IF(AND(NDF[[#This Row],[Type de dépense]]="Repas",NDF[[#This Row],[Déjeuner/Dîner]]="Déjeuner"),IF(NDF[[#This Row],[Total]]/NDF[[#This Row],[Nb de pers]]<(Limit_dej+0.01),NDF[[#This Row],[Total]],NDF[[#This Row],[Nb de pers]]*Limit_dej),IF(AND(NDF[[#This Row],[Type de dépense]]="Repas",NDF[[#This Row],[Déjeuner/Dîner]]="Dîner"),IF(NDF[[#This Row],[Total]]/NDF[[#This Row],[Nb de pers]]<Limit_Diner+0.01,NDF[[#This Row],[Total]],NDF[[#This Row],[Nb de pers]]*Limit_Diner),IF(NDF[[#This Row],[Type de dépense]]="Véhicule Personnel (trajet en Km Ecole/Salon)",NDF[[#This Row],[Total]]*Coeff_Fiscal,IF(AND(NDF[[#This Row],[Type de dépense]]="Repas",OR(NDF[[#This Row],[Déjeuner/Dîner]]="",NDF[[#This Row],[Nb de pers]]="")),"",NDF[[#This Row],[Total]])))))))))) -> 0 | L20: =IF(NDF[[#This Row],[Remboursement Calculé]]="","",IF(ISNA(INDEX(Mapping_Comptable[Libellé comptable],MATCH(CONCATENATE(NDF[[#This Row],[Evénement]],"/",NDF[[#This Row],[Type de dépense]]),Mapping_Comptable[Column1],0),0)),"en attente",IF(AND(NDF[[#This Row],[Type de dépense]]="Repas",OR(NDF[[#This Row],[Déjeuner/Dîner]]="",NDF[[#This Row],[Nb de pers]]="")),"",INDEX(Mapping_Comptable[Compte Comptable],MATCH(CONCATENATE(NDF[[#This Row],[Evénement]],"/",NDF[[#This Row],[Type de dépense]]),Mapping_Comptable[Column1],0),0)))) -> en attente | M20: =IF(NDF[[#This Row],[Remboursement Calculé]]="","en attente",IF(ISNA(INDEX(Mapping_Comptable[Libellé comptable],MATCH(CONCATENATE(NDF[[#This Row],[Evénement]],"/",NDF[[#This Row],[Type de dépense]]),Mapping_Comptable[Column1],0),0)),"en attente",IF(AND(NDF[[#This Row],[Type de dépense]]="Repas",OR(NDF[[#This Row],[Déjeuner/Dîner]]="",NDF[[#This Row],[Nb de pers]]="")),"",INDEX(Mapping_Comptable[Libellé comptable],MATCH(CONCATENATE(NDF[[#This Row],[Evénement]],"/",NDF[[#This Row],[Type de dépense]]),Mapping_Comptable[Column1],0),0)))) -> en attente | N20: =IF(B20="","",VLOOKUP(B20,Paramétrage!$E$2:$F$12,2,FALSE)) | O20: =IF(AND(NDF[[#This Row],[Ecole/Prog/Dépt]]="",NDF[[#This Row],[Ville]]=""),$B$6&$B$7,IF(AND(NDF[[#This Row],[Ecole/Prog/Dépt]]="",NDF[[#This Row],[Ville]]<>""),$B$6&NDF[[#This Row],[Ville]],IF(AND(NDF[[#This Row],[Ecole/Prog/Dépt]]<>"",NDF[[#This Row],[Ville]]=""),NDF[[#This Row],[Ecole/Prog/Dépt]]&$B$7,IF(AND(NDF[[#This Row],[Ecole/Prog/Dépt]]<>"",NDF[[#This Row],[Ville]]<>""),NDF[[#This Row],[Ecole/Prog/Dépt]]&NDF[[#This Row],[Ville]],"")))) -> EPITECH ITPARIS et RP | P20: =VLOOKUP(NDF[[#This Row],[Colonne1]],Paramétrage!$L$73:$M$223,2,FALSE) -> 0068 - IT PARIS | Q20: Montant NDF | R20: =HLOOKUP(NDF[[#This Row],[Evénement]],Paramétrage!$L$1:$P$2,2,0) -> #N/A | S20: =IF(AND(NDF[[#This Row],[Remboursement Calculé]]="",NDF[[#This Row],[Libellé de compte]]="en attente",NDF[[#This Row],[Type de dépense]]="Véhicule Personnel (trajet en Km Ecole/Salon)"),"Trajet ! Veuillez renseigner la puissance Fiscale de votre véhicule",IF(AND(NDF[[#This Row],[Evénement]]="Autre",NDF[[#This Row],[Type de dépense]]="Autre"),"En attente affectation par le comptable, renseigner un commentaire",IF(AND(NDF[[#This Row],[Remboursement Calculé]]>0,NDF[[#This Row],[Libellé de compte]]="en attente"),"Attention Evénement et Type de Dépense INCOMPATIBLES",IF(AND(NDF[[#This Row],[Type de dépense]]="Repas",OR(NDF[[#This Row],[Déjeuner/Dîner]]="",NDF[[#This Row],[Nb de pers]]="")),"Attention type de Dépense 'Repas' renseignez aussi le Type de Repas et/ou le nb de pers",IF(AND($B$7="",NDF[[#This Row],[Ville]]=""),"Ville non renseignée",IF(AND($B$6="",NDF[[#This Row],[Ecole/Prog/Dépt]]=""),"Ecole/Prog/Dépt non renseignés",""))))))
A21: 5 | K21: =IF(AND(NDF[[#This Row],[Type de dépense]]="Repas",NDF[[#This Row],[Déjeuner/Dîner]]="Dîner",Limit_Diner=0),NDF[[#This Row],[Total]],IF(AND(NDF[[#This Row],[Type de dépense]]="Repas",NDF[[#This Row],[Déjeuner/Dîner]]="Déjeuner",Limit_dej=0),NDF[[#This Row],[Total]],IF(AND(NDF[[#This Row],[Type de dépense]]="Hébergement",Hotel=0),NDF[[#This Row],[Total]],IF(AND(NDF[[#This Row],[Type de dépense]]="Hébergement",NDF[[#This Row],[Total]]>Hotel),Hotel,IF(AND(NDF[[#This Row],[Type de dépense]]="Véhicule Personnel (trajet en Km Ecole/Salon)",Puissance_Fiscale=""),"",IF(AND(NDF[[#This Row],[Type de dépense]]="Repas",NDF[[#This Row],[Déjeuner/Dîner]]<>0,NDF[[#This Row],[Nb de pers]]=""),"",IF(AND(NDF[[#This Row],[Type de dépense]]="Repas",NDF[[#This Row],[Déjeuner/Dîner]]="Déjeuner"),IF(NDF[[#This Row],[Total]]/NDF[[#This Row],[Nb de pers]]<(Limit_dej+0.01),NDF[[#This Row],[Total]],NDF[[#This Row],[Nb de pers]]*Limit_dej),IF(AND(NDF[[#This Row],[Type de dépense]]="Repas",NDF[[#This Row],[Déjeuner/Dîner]]="Dîner"),IF(NDF[[#This Row],[Total]]/NDF[[#This Row],[Nb de pers]]<Limit_Diner+0.01,NDF[[#This Row],[Total]],NDF[[#This Row],[Nb de pers]]*Limit_Diner),IF(NDF[[#This Row],[Type de dépense]]="Véhicule Personnel (trajet en Km Ecole/Salon)",NDF[[#This Row],[Total]]*Coeff_Fiscal,IF(AND(NDF[[#This Row],[Type de dépense]]="Repas",OR(NDF[[#This Row],[Déjeuner/Dîner]]="",NDF[[#This Row],[Nb de pers]]="")),"",NDF[[#This Row],[Total]])))))))))) -> 0 | L21: =IF(NDF[[#This Row],[Remboursement Calculé]]="","",IF(ISNA(INDEX(Mapping_Comptable[Libellé comptable],MATCH(CONCATENATE(NDF[[#This Row],[Evénement]],"/",NDF[[#This Row],[Type de dépense]]),Mapping_Comptable[Column1],0),0)),"en attente",IF(AND(NDF[[#This Row],[Type de dépense]]="Repas",OR(NDF[[#This Row],[Déjeuner/Dîner]]="",NDF[[#This Row],[Nb de pers]]="")),"",INDEX(Mapping_Comptable[Compte Comptable],MATCH(CONCATENATE(NDF[[#This Row],[Evénement]],"/",NDF[[#This Row],[Type de dépense]]),Mapping_Comptable[Column1],0),0)))) -> en attente | M21: =IF(NDF[[#This Row],[Remboursement Calculé]]="","en attente",IF(ISNA(INDEX(Mapping_Comptable[Libellé comptable],MATCH(CONCATENATE(NDF[[#This Row],[Evénement]],"/",NDF[[#This Row],[Type de dépense]]),Mapping_Comptable[Column1],0),0)),"en attente",IF(AND(NDF[[#This Row],[Type de dépense]]="Repas",OR(NDF[[#This Row],[Déjeuner/Dîner]]="",NDF[[#This Row],[Nb de pers]]="")),"",INDEX(Mapping_Comptable[Libellé comptable],MATCH(CONCATENATE(NDF[[#This Row],[Evénement]],"/",NDF[[#This Row],[Type de dépense]]),Mapping_Comptable[Column1],0),0)))) -> en attente | N21: =IF(B21="","",VLOOKUP(B21,Paramétrage!$E$2:$F$12,2,FALSE)) | O21: =IF(AND(NDF[[#This Row],[Ecole/Prog/Dépt]]="",NDF[[#This Row],[Ville]]=""),$B$6&$B$7,IF(AND(NDF[[#This Row],[Ecole/Prog/Dépt]]="",NDF[[#This Row],[Ville]]<>""),$B$6&NDF[[#This Row],[Ville]],IF(AND(NDF[[#This Row],[Ecole/Prog/Dépt]]<>"",NDF[[#This Row],[Ville]]=""),NDF[[#This Row],[Ecole/Prog/Dépt]]&$B$7,IF(AND(NDF[[#This Row],[Ecole/Prog/Dépt]]<>"",NDF[[#This Row],[Ville]]<>""),NDF[[#This Row],[Ecole/Prog/Dépt]]&NDF[[#This Row],[Ville]],"")))) -> EPITECH ITPARIS et RP | P21: =VLOOKUP(NDF[[#This Row],[Colonne1]],Paramétrage!$L$73:$M$223,2,FALSE) -> 0068 - IT PARIS | Q21: Montant NDF | R21: =HLOOKUP(NDF[[#This Row],[Evénement]],Paramétrage!$L$1:$P$2,2,0) -> #N/A | S21: =IF(AND(NDF[[#This Row],[Remboursement Calculé]]="",NDF[[#This Row],[Libellé de compte]]="en attente",NDF[[#This Row],[Type de dépense]]="Véhicule Personnel (trajet en Km Ecole/Salon)"),"Trajet ! Veuillez renseigner la puissance Fiscale de votre véhicule",IF(AND(NDF[[#This Row],[Evénement]]="Autre",NDF[[#This Row],[Type de dépense]]="Autre"),"En attente affectation par le comptable, renseigner un commentaire",IF(AND(NDF[[#This Row],[Remboursement Calculé]]>0,NDF[[#This Row],[Libellé de compte]]="en attente"),"Attention Evénement et Type de Dépense INCOMPATIBLES",IF(AND(NDF[[#This Row],[Type de dépense]]="Repas",OR(NDF[[#This Row],[Déjeuner/Dîner]]="",NDF[[#This Row],[Nb de pers]]="")),"Attention type de Dépense 'Repas' renseignez aussi le Type de Repas et/ou le nb de pers",IF(AND($B$7="",NDF[[#This Row],[Ville]]=""),"Ville non renseignée",IF(AND($B$6="",NDF[[#This Row],[Ecole/Prog/Dépt]]=""),"Ecole/Prog/Dépt non renseignés",""))))))
A22: 6 | K22: =IF(AND(NDF[[#This Row],[Type de dépense]]="Repas",NDF[[#This Row],[Déjeuner/Dîner]]="Dîner",Limit_Diner=0),NDF[[#This Row],[Total]],IF(AND(NDF[[#This Row],[Type de dépense]]="Repas",NDF[[#This Row],[Déjeuner/Dîner]]="Déjeuner",Limit_dej=0),NDF[[#This Row],[Total]],IF(AND(NDF[[#This Row],[Type de dépense]]="Hébergement",Hotel=0),NDF[[#This Row],[Total]],IF(AND(NDF[[#This Row],[Type de dépense]]="Hébergement",NDF[[#This Row],[Total]]>Hotel),Hotel,IF(AND(NDF[[#This Row],[Type de dépense]]="Véhicule Personnel (trajet en Km Ecole/Salon)",Puissance_Fiscale=""),"",IF(AND(NDF[[#This Row],[Type de dépense]]="Repas",NDF[[#This Row],[Déjeuner/Dîner]]<>0,NDF[[#This Row],[Nb de pers]]=""),"",IF(AND(NDF[[#This Row],[Type de dépense]]="Repas",NDF[[#This Row],[Déjeuner/Dîner]]="Déjeuner"),IF(NDF[[#This Row],[Total]]/NDF[[#This Row],[Nb de pers]]<(Limit_dej+0.01),NDF[[#This Row],[Total]],NDF[[#This Row],[Nb de pers]]*Limit_dej),IF(AND(NDF[[#This Row],[Type de dépense]]="Repas",NDF[[#This Row],[Déjeuner/Dîner]]="Dîner"),IF(NDF[[#This Row],[Total]]/NDF[[#This Row],[Nb de pers]]<Limit_Diner+0.01,NDF[[#This Row],[Total]],NDF[[#This Row],[Nb de pers]]*Limit_Diner),IF(NDF[[#This Row],[Type de dépense]]="Véhicule Personnel (trajet en Km Ecole/Salon)",NDF[[#This Row],[Total]]*Coeff_Fiscal,IF(AND(NDF[[#This Row],[Type de dépense]]="Repas",OR(NDF[[#This Row],[Déjeuner/Dîner]]="",NDF[[#This Row],[Nb de pers]]="")),"",NDF[[#This Row],[Total]])))))))))) -> 0 | L22: =IF(NDF[[#This Row],[Remboursement Calculé]]="","",IF(ISNA(INDEX(Mapping_Comptable[Libellé comptable],MATCH(CONCATENATE(NDF[[#This Row],[Evénement]],"/",NDF[[#This Row],[Type de dépense]]),Mapping_Comptable[Column1],0),0)),"en attente",IF(AND(NDF[[#This Row],[Type de dépense]]="Repas",OR(NDF[[#This Row],[Déjeuner/Dîner]]="",NDF[[#This Row],[Nb de pers]]="")),"",INDEX(Mapping_Comptable[Compte Comptable],MATCH(CONCATENATE(NDF[[#This Row],[Evénement]],"/",NDF[[#This Row],[Type de dépense]]),Mapping_Comptable[Column1],0),0)))) -> en attente | M22: =IF(NDF[[#This Row],[Remboursement Calculé]]="","en attente",IF(ISNA(INDEX(Mapping_Comptable[Libellé comptable],MATCH(CONCATENATE(NDF[[#This Row],[Evénement]],"/",NDF[[#This Row],[Type de dépense]]),Mapping_Comptable[Column1],0),0)),"en attente",IF(AND(NDF[[#This Row],[Type de dépense]]="Repas",OR(NDF[[#This Row],[Déjeuner/Dîner]]="",NDF[[#This Row],[Nb de pers]]="")),"",INDEX(Mapping_Comptable[Libellé comptable],MATCH(CONCATENATE(NDF[[#This Row],[Evénement]],"/",NDF[[#This Row],[Type de dépense]]),Mapping_Comptable[Column1],0),0)))) -> en attente | N22: =IF(B22="","",VLOOKUP(B22,Paramétrage!$E$2:$F$12,2,FALSE)) | O22: =IF(AND(NDF[[#This Row],[Ecole/Prog/Dépt]]="",NDF[[#This Row],[Ville]]=""),$B$6&$B$7,IF(AND(NDF[[#This Row],[Ecole/Prog/Dépt]]="",NDF[[#This Row],[Ville]]<>""),$B$6&NDF[[#This Row],[Ville]],IF(AND(NDF[[#This Row],[Ecole/Prog/Dépt]]<>"",NDF[[#This Row],[Ville]]=""),NDF[[#This Row],[Ecole/Prog/Dépt]]&$B$7,IF(AND(NDF[[#This Row],[Ecole/Prog/Dépt]]<>"",NDF[[#This Row],[Ville]]<>""),NDF[[#This Row],[Ecole/Prog/Dépt]]&NDF[[#This Row],[Ville]],"")))) -> EPITECH ITPARIS et RP | P22: =VLOOKUP(NDF[[#This Row],[Colonne1]],Paramétrage!$L$73:$M$223,2,FALSE) -> 0068 - IT PARIS | Q22: Montant NDF | R22: =HLOOKUP(NDF[[#This Row],[Evénement]],Paramétrage!$L$1:$P$2,2,0) -> #N/A | S22: =IF(AND(NDF[[#This Row],[Remboursement Calculé]]="",NDF[[#This Row],[Libellé de compte]]="en attente",NDF[[#This Row],[Type de dépense]]="Véhicule Personnel (trajet en Km Ecole/Salon)"),"Trajet ! Veuillez renseigner la puissance Fiscale de votre véhicule",IF(AND(NDF[[#This Row],[Evénement]]="Autre",NDF[[#This Row],[Type de dépense]]="Autre"),"En attente affectation par le comptable, renseigner un commentaire",IF(AND(NDF[[#This Row],[Remboursement Calculé]]>0,NDF[[#This Row],[Libellé de compte]]="en attente"),"Attention Evénement et Type de Dépense INCOMPATIBLES",IF(AND(NDF[[#This Row],[Type de dépense]]="Repas",OR(NDF[[#This Row],[Déjeuner/Dîner]]="",NDF[[#This Row],[Nb de pers]]="")),"Attention type de Dépense 'Repas' renseignez aussi le Type de Repas et/ou le nb de pers",IF(AND($B$7="",NDF[[#This Row],[Ville]]=""),"Ville non renseignée",IF(AND($B$6="",NDF[[#This Row],[Ecole/Prog/Dépt]]=""),"Ecole/Prog/Dépt non renseignés",""))))))
A23: 7 | K23: =IF(AND(NDF[[#This Row],[Type de dépense]]="Repas",NDF[[#This Row],[Déjeuner/Dîner]]="Dîner",Limit_Diner=0),NDF[[#This Row],[Total]],IF(AND(NDF[[#This Row],[Type de dépense]]="Repas",NDF[[#This Row],[Déjeuner/Dîner]]="Déjeuner",Limit_dej=0),NDF[[#This Row],[Total]],IF(AND(NDF[[#This Row],[Type de dépense]]="Hébergement",Hotel=0),NDF[[#This Row],[Total]],IF(AND(NDF[[#This Row],[Type de dépense]]="Hébergement",NDF[[#This Row],[Total]]>Hotel),Hotel,IF(AND(NDF[[#This Row],[Type de dépense]]="Véhicule Personnel (trajet en Km Ecole/Salon)",Puissance_Fiscale=""),"",IF(AND(NDF[[#This Row],[Type de dépense]]="Repas",NDF[[#This Row],[Déjeuner/Dîner]]<>0,NDF[[#This Row],[Nb de pers]]=""),"",IF(AND(NDF[[#This Row],[Type de dépense]]="Repas",NDF[[#This Row],[Déjeuner/Dîner]]="Déjeuner"),IF(NDF[[#This Row],[Total]]/NDF[[#This Row],[Nb de pers]]<(Limit_dej+0.01),NDF[[#This Row],[Total]],NDF[[#This Row],[Nb de pers]]*Limit_dej),IF(AND(NDF[[#This Row],[Type de dépense]]="Repas",NDF[[#This Row],[Déjeuner/Dîner]]="Dîner"),IF(NDF[[#This Row],[Total]]/NDF[[#This Row],[Nb de pers]]<Limit_Diner+0.01,NDF[[#This Row],[Total]],NDF[[#This Row],[Nb de pers]]*Limit_Diner),IF(NDF[[#This Row],[Type de dépense]]="Véhicule Personnel (trajet en Km Ecole/Salon)",NDF[[#This Row],[Total]]*Coeff_Fiscal,IF(AND(NDF[[#This Row],[Type de dépense]]="Repas",OR(NDF[[#This Row],[Déjeuner/Dîner]]="",NDF[[#This Row],[Nb de pers]]="")),"",NDF[[#This Row],[Total]])))))))))) -> 0 | L23: =IF(NDF[[#This Row],[Remboursement Calculé]]="","",IF(ISNA(INDEX(Mapping_Comptable[Libellé comptable],MATCH(CONCATENATE(NDF[[#This Row],[Evénement]],"/",NDF[[#This Row],[Type de dépense]]),Mapping_Comptable[Column1],0),0)),"en attente",IF(AND(NDF[[#This Row],[Type de dépense]]="Repas",OR(NDF[[#This Row],[Déjeuner/Dîner]]="",NDF[[#This Row],[Nb de pers]]="")),"",INDEX(Mapping_Comptable[Compte Comptable],MATCH(CONCATENATE(NDF[[#This Row],[Evénement]],"/",NDF[[#This Row],[Type de dépense]]),Mapping_Comptable[Column1],0),0)))) -> en attente | M23: =IF(NDF[[#This Row],[Remboursement Calculé]]="","en attente",IF(ISNA(INDEX(Mapping_Comptable[Libellé comptable],MATCH(CONCATENATE(NDF[[#This Row],[Evénement]],"/",NDF[[#This Row],[Type de dépense]]),Mapping_Comptable[Column1],0),0)),"en attente",IF(AND(NDF[[#This Row],[Type de dépense]]="Repas",OR(NDF[[#This Row],[Déjeuner/Dîner]]="",NDF[[#This Row],[Nb de pers]]="")),"",INDEX(Mapping_Comptable[Libellé comptable],MATCH(CONCATENATE(NDF[[#This Row],[Evénement]],"/",NDF[[#This Row],[Type de dépense]]),Mapping_Comptable[Column1],0),0)))) -> en attente | N23: =IF(B23="","",VLOOKUP(B23,Paramétrage!$E$2:$F$12,2,FALSE)) | O23: =IF(AND(NDF[[#This Row],[Ecole/Prog/Dépt]]="",NDF[[#This Row],[Ville]]=""),$B$6&$B$7,IF(AND(NDF[[#This Row],[Ecole/Prog/Dépt]]="",NDF[[#This Row],[Ville]]<>""),$B$6&NDF[[#This Row],[Ville]],IF(AND(NDF[[#This Row],[Ecole/Prog/Dépt]]<>"",NDF[[#This Row],[Ville]]=""),NDF[[#This Row],[Ecole/Prog/Dépt]]&$B$7,IF(AND(NDF[[#This Row],[Ecole/Prog/Dépt]]<>"",NDF[[#This Row],[Ville]]<>""),NDF[[#This Row],[Ecole/Prog/Dépt]]&NDF[[#This Row],[Ville]],"")))) -> EPITECH ITPARIS et RP | P23: =VLOOKUP(NDF[[#This Row],[Colonne1]],Paramétrage!$L$73:$M$223,2,FALSE) -> 0068 - IT PARIS | Q23: Montant NDF | R23: =HLOOKUP(NDF[[#This Row],[Evénement]],Paramétrage!$L$1:$P$2,2,0) -> #N/A | S23: =IF(AND(NDF[[#This Row],[Remboursement Calculé]]="",NDF[[#This Row],[Libellé de compte]]="en attente",NDF[[#This Row],[Type de dépense]]="Véhicule Personnel (trajet en Km Ecole/Salon)"),"Trajet ! Veuillez renseigner la puissance Fiscale de votre véhicule",IF(AND(NDF[[#This Row],[Evénement]]="Autre",NDF[[#This Row],[Type de dépense]]="Autre"),"En attente affectation par le comptable, renseigner un commentaire",IF(AND(NDF[[#This Row],[Remboursement Calculé]]>0,NDF[[#This Row],[Libellé de compte]]="en attente"),"Attention Evénement et Type de Dépense INCOMPATIBLES",IF(AND(NDF[[#This Row],[Type de dépense]]="Repas",OR(NDF[[#This Row],[Déjeuner/Dîner]]="",NDF[[#This Row],[Nb de pers]]="")),"Attention type de Dépense 'Repas' renseignez aussi le Type de Repas et/ou le nb de pers",IF(AND($B$7="",NDF[[#This Row],[Ville]]=""),"Ville non renseignée",IF(AND($B$6="",NDF[[#This Row],[Ecole/Prog/Dépt]]=""),"Ecole/Prog/Dépt non renseignés",""))))))
A24: 8 | K24: =IF(AND(NDF[[#This Row],[Type de dépense]]="Repas",NDF[[#This Row],[Déjeuner/Dîner]]="Dîner",Limit_Diner=0),NDF[[#This Row],[Total]],IF(AND(NDF[[#This Row],[Type de dépense]]="Repas",NDF[[#This Row],[Déjeuner/Dîner]]="Déjeuner",Limit_dej=0),NDF[[#This Row],[Total]],IF(AND(NDF[[#This Row],[Type de dépense]]="Hébergement",Hotel=0),NDF[[#This Row],[Total]],IF(AND(NDF[[#This Row],[Type de dépense]]="Hébergement",NDF[[#This Row],[Total]]>Hotel),Hotel,IF(AND(NDF[[#This Row],[Type de dépense]]="Véhicule Personnel (trajet en Km Ecole/Salon)",Puissance_Fiscale=""),"",IF(AND(NDF[[#This Row],[Type de dépense]]="Repas",NDF[[#This Row],[Déjeuner/Dîner]]<>0,NDF[[#This Row],[Nb de pers]]=""),"",IF(AND(NDF[[#This Row],[Type de dépense]]="Repas",NDF[[#This Row],[Déjeuner/Dîner]]="Déjeuner"),IF(NDF[[#This Row],[Total]]/NDF[[#This Row],[Nb de pers]]<(Limit_dej+0.01),NDF[[#This Row],[Total]],NDF[[#This Row],[Nb de pers]]*Limit_dej),IF(AND(NDF[[#This Row],[Type de dépense]]="Repas",NDF[[#This Row],[Déjeuner/Dîner]]="Dîner"),IF(NDF[[#This Row],[Total]]/NDF[[#This Row],[Nb de pers]]<Limit_Diner+0.01,NDF[[#This Row],[Total]],NDF[[#This Row],[Nb de pers]]*Limit_Diner),IF(NDF[[#This Row],[Type de dépense]]="Véhicule Personnel (trajet en Km Ecole/Salon)",NDF[[#This Row],[Total]]*Coeff_Fiscal,IF(AND(NDF[[#This Row],[Type de dépense]]="Repas",OR(NDF[[#This Row],[Déjeuner/Dîner]]="",NDF[[#This Row],[Nb de pers]]="")),"",NDF[[#This Row],[Total]])))))))))) -> 0 | L24: =IF(NDF[[#This Row],[Remboursement Calculé]]="","",IF(ISNA(INDEX(Mapping_Comptable[Libellé comptable],MATCH(CONCATENATE(NDF[[#This Row],[Evénement]],"/",NDF[[#This Row],[Type de dépense]]),Mapping_Comptable[Column1],0),0)),"en attente",IF(AND(NDF[[#This Row],[Type de dépense]]="Repas",OR(NDF[[#This Row],[Déjeuner/Dîner]]="",NDF[[#This Row],[Nb de pers]]="")),"",INDEX(Mapping_Comptable[Compte Comptable],MATCH(CONCATENATE(NDF[[#This Row],[Evénement]],"/",NDF[[#This Row],[Type de dépense]]),Mapping_Comptable[Column1],0),0)))) -> en attente | M24: =IF(NDF[[#This Row],[Remboursement Calculé]]="","en attente",IF(ISNA(INDEX(Mapping_Comptable[Libellé comptable],MATCH(CONCATENATE(NDF[[#This Row],[Evénement]],"/",NDF[[#This Row],[Type de dépense]]),Mapping_Comptable[Column1],0),0)),"en attente",IF(AND(NDF[[#This Row],[Type de dépense]]="Repas",OR(NDF[[#This Row],[Déjeuner/Dîner]]="",NDF[[#This Row],[Nb de pers]]="")),"",INDEX(Mapping_Comptable[Libellé comptable],MATCH(CONCATENATE(NDF[[#This Row],[Evénement]],"/",NDF[[#This Row],[Type de dépense]]),Mapping_Comptable[Column1],0),0)))) -> en attente | N24: =IF(B24="","",VLOOKUP(B24,Paramétrage!$E$2:$F$12,2,FALSE)) | O24: =IF(AND(NDF[[#This Row],[Ecole/Prog/Dépt]]="",NDF[[#This Row],[Ville]]=""),$B$6&$B$7,IF(AND(NDF[[#This Row],[Ecole/Prog/Dépt]]="",NDF[[#This Row],[Ville]]<>""),$B$6&NDF[[#This Row],[Ville]],IF(AND(NDF[[#This Row],[Ecole/Prog/Dépt]]<>"",NDF[[#This Row],[Ville]]=""),NDF[[#This Row],[Ecole/Prog/Dépt]]&$B$7,IF(AND(NDF[[#This Row],[Ecole/Prog/Dépt]]<>"",NDF[[#This Row],[Ville]]<>""),NDF[[#This Row],[Ecole/Prog/Dépt]]&NDF[[#This Row],[Ville]],"")))) -> EPITECH ITPARIS et RP | P24: =VLOOKUP(NDF[[#This Row],[Colonne1]],Paramétrage!$L$73:$M$223,2,FALSE) -> 0068 - IT PARIS | Q24: Montant NDF | R24: =HLOOKUP(NDF[[#This Row],[Evénement]],Paramétrage!$L$1:$P$2,2,0) -> #N/A | S24: =IF(AND(NDF[[#This Row],[Remboursement Calculé]]="",NDF[[#This Row],[Libellé de compte]]="en attente",NDF[[#This Row],[Type de dépense]]="Véhicule Personnel (trajet en Km Ecole/Salon)"),"Trajet ! Veuillez renseigner la puissance Fiscale de votre véhicule",IF(AND(NDF[[#This Row],[Evénement]]="Autre",NDF[[#This Row],[Type de dépense]]="Autre"),"En attente affectation par le comptable, renseigner un commentaire",IF(AND(NDF[[#This Row],[Remboursement Calculé]]>0,NDF[[#This Row],[Libellé de compte]]="en attente"),"Attention Evénement et Type de Dépense INCOMPATIBLES",IF(AND(NDF[[#This Row],[Type de dépense]]="Repas",OR(NDF[[#This Row],[Déjeuner/Dîner]]="",NDF[[#This Row],[Nb de pers]]="")),"Attention type de Dépense 'Repas' renseignez aussi le Type de Repas et/ou le nb de pers",IF(AND($B$7="",NDF[[#This Row],[Ville]]=""),"Ville non renseignée",IF(AND($B$6="",NDF[[#This Row],[Ecole/Prog/Dépt]]=""),"Ecole/Prog/Dépt non renseignés",""))))))
A25: 9 | K25: =IF(AND(NDF[[#This Row],[Type de dépense]]="Repas",NDF[[#This Row],[Déjeuner/Dîner]]="Dîner",Limit_Diner=0),NDF[[#This Row],[Total]],IF(AND(NDF[[#This Row],[Type de dépense]]="Repas",NDF[[#This Row],[Déjeuner/Dîner]]="Déjeuner",Limit_dej=0),NDF[[#This Row],[Total]],IF(AND(NDF[[#This Row],[Type de dépense]]="Hébergement",Hotel=0),NDF[[#This Row],[Total]],IF(AND(NDF[[#This Row],[Type de dépense]]="Hébergement",NDF[[#This Row],[Total]]>Hotel),Hotel,IF(AND(NDF[[#This Row],[Type de dépense]]="Véhicule Personnel (trajet en Km Ecole/Salon)",Puissance_Fiscale=""),"",IF(AND(NDF[[#This Row],[Type de dépense]]="Repas",NDF[[#This Row],[Déjeuner/Dîner]]<>0,NDF[[#This Row],[Nb de pers]]=""),"",IF(AND(NDF[[#This Row],[Type de dépense]]="Repas",NDF[[#This Row],[Déjeuner/Dîner]]="Déjeuner"),IF(NDF[[#This Row],[Total]]/NDF[[#This Row],[Nb de pers]]<(Limit_dej+0.01),NDF[[#This Row],[Total]],NDF[[#This Row],[Nb de pers]]*Limit_dej),IF(AND(NDF[[#This Row],[Type de dépense]]="Repas",NDF[[#This Row],[Déjeuner/Dîner]]="Dîner"),IF(NDF[[#This Row],[Total]]/NDF[[#This Row],[Nb de pers]]<Limit_Diner+0.01,NDF[[#This Row],[Total]],NDF[[#This Row],[Nb de pers]]*Limit_Diner),IF(NDF[[#This Row],[Type de dépense]]="Véhicule Personnel (trajet en Km Ecole/Salon)",NDF[[#This Row],[Total]]*Coeff_Fiscal,IF(AND(NDF[[#This Row],[Type de dépense]]="Repas",OR(NDF[[#This Row],[Déjeuner/Dîner]]="",NDF[[#This Row],[Nb de pers]]="")),"",NDF[[#This Row],[Total]])))))))))) -> 0 | L25: =IF(NDF[[#This Row],[Remboursement Calculé]]="","",IF(ISNA(INDEX(Mapping_Comptable[Libellé comptable],MATCH(CONCATENATE(NDF[[#This Row],[Evénement]],"/",NDF[[#This Row],[Type de dépense]]),Mapping_Comptable[Column1],0),0)),"en attente",IF(AND(NDF[[#This Row],[Type de dépense]]="Repas",OR(NDF[[#This Row],[Déjeuner/Dîner]]="",NDF[[#This Row],[Nb de pers]]="")),"",INDEX(Mapping_Comptable[Compte Comptable],MATCH(CONCATENATE(NDF[[#This Row],[Evénement]],"/",NDF[[#This Row],[Type de dépense]]),Mapping_Comptable[Column1],0),0)))) -> en attente | M25: =IF(NDF[[#This Row],[Remboursement Calculé]]="","en attente",IF(ISNA(INDEX(Mapping_Comptable[Libellé comptable],MATCH(CONCATENATE(NDF[[#This Row],[Evénement]],"/",NDF[[#This Row],[Type de dépense]]),Mapping_Comptable[Column1],0),0)),"en attente",IF(AND(NDF[[#This Row],[Type de dépense]]="Repas",OR(NDF[[#This Row],[Déjeuner/Dîner]]="",NDF[[#This Row],[Nb de pers]]="")),"",INDEX(Mapping_Comptable[Libellé comptable],MATCH(CONCATENATE(NDF[[#This Row],[Evénement]],"/",NDF[[#This Row],[Type de dépense]]),Mapping_Comptable[Column1],0),0)))) -> en attente | N25: =IF(B25="","",VLOOKUP(B25,Paramétrage!$E$2:$F$12,2,FALSE)) | O25: =IF(AND(NDF[[#This Row],[Ecole/Prog/Dépt]]="",NDF[[#This Row],[Ville]]=""),$B$6&$B$7,IF(AND(NDF[[#This Row],[Ecole/Prog/Dépt]]="",NDF[[#This Row],[Ville]]<>""),$B$6&NDF[[#This Row],[Ville]],IF(AND(NDF[[#This Row],[Ecole/Prog/Dépt]]<>"",NDF[[#This Row],[Ville]]=""),NDF[[#This Row],[Ecole/Prog/Dépt]]&$B$7,IF(AND(NDF[[#This Row],[Ecole/Prog/Dépt]]<>"",NDF[[#This Row],[Ville]]<>""),NDF[[#This Row],[Ecole/Prog/Dépt]]&NDF[[#This Row],[Ville]],"")))) -> EPITECH ITPARIS et RP | P25: =VLOOKUP(NDF[[#This Row],[Colonne1]],Paramétrage!$L$73:$M$223,2,FALSE) -> 0068 - IT PARIS | Q25: Montant NDF | R25: =HLOOKUP(NDF[[#This Row],[Evénement]],Paramétrage!$L$1:$P$2,2,0) -> #N/A | S25: =IF(AND(NDF[[#This Row],[Remboursement Calculé]]="",NDF[[#This Row],[Libellé de compte]]="en attente",NDF[[#This Row],[Type de dépense]]="Véhicule Personnel (trajet en Km Ecole/Salon)"),"Trajet ! Veuillez renseigner la puissance Fiscale de votre véhicule",IF(AND(NDF[[#This Row],[Evénement]]="Autre",NDF[[#This Row],[Type de dépense]]="Autre"),"En attente affectation par le comptable, renseigner un commentaire",IF(AND(NDF[[#This Row],[Remboursement Calculé]]>0,NDF[[#This Row],[Libellé de compte]]="en attente"),"Attention Evénement et Type de Dépense INCOMPATIBLES",IF(AND(NDF[[#This Row],[Type de dépense]]="Repas",OR(NDF[[#This Row],[Déjeuner/Dîner]]="",NDF[[#This Row],[Nb de pers]]="")),"Attention type de Dépense 'Repas' renseignez aussi le Type de Repas et/ou le nb de pers",IF(AND($B$7="",NDF[[#This Row],[Ville]]=""),"Ville non renseignée",IF(AND($B$6="",NDF[[#This Row],[Ecole/Prog/Dépt]]=""),"Ecole/Prog/Dépt non renseignés",""))))))
A26: 10 | K26: =IF(AND(NDF[[#This Row],[Type de dépense]]="Repas",NDF[[#This Row],[Déjeuner/Dîner]]="Dîner",Limit_Diner=0),NDF[[#This Row],[Total]],IF(AND(NDF[[#This Row],[Type de dépense]]="Repas",NDF[[#This Row],[Déjeuner/Dîner]]="Déjeuner",Limit_dej=0),NDF[[#This Row],[Total]],IF(AND(NDF[[#This Row],[Type de dépense]]="Hébergement",Hotel=0),NDF[[#This Row],[Total]],IF(AND(NDF[[#This Row],[Type de dépense]]="Hébergement",NDF[[#This Row],[Total]]>Hotel),Hotel,IF(AND(NDF[[#This Row],[Type de dépense]]="Véhicule Personnel (trajet en Km Ecole/Salon)",Puissance_Fiscale=""),"",IF(AND(NDF[[#This Row],[Type de dépense]]="Repas",NDF[[#This Row],[Déjeuner/Dîner]]<>0,NDF[[#This Row],[Nb de pers]]=""),"",IF(AND(NDF[[#This Row],[Type de dépense]]="Repas",NDF[[#This Row],[Déjeuner/Dîner]]="Déjeuner"),IF(NDF[[#This Row],[Total]]/NDF[[#This Row],[Nb de pers]]<(Limit_dej+0.01),NDF[[#This Row],[Total]],NDF[[#This Row],[Nb de pers]]*Limit_dej),IF(AND(NDF[[#This Row],[Type de dépense]]="Repas",NDF[[#This Row],[Déjeuner/Dîner]]="Dîner"),IF(NDF[[#This Row],[Total]]/NDF[[#This Row],[Nb de pers]]<Limit_Diner+0.01,NDF[[#This Row],[Total]],NDF[[#This Row],[Nb de pers]]*Limit_Diner),IF(NDF[[#This Row],[Type de dépense]]="Véhicule Personnel (trajet en Km Ecole/Salon)",NDF[[#This Row],[Total]]*Coeff_Fiscal,IF(AND(NDF[[#This Row],[Type de dépense]]="Repas",OR(NDF[[#This Row],[Déjeuner/Dîner]]="",NDF[[#This Row],[Nb de pers]]="")),"",NDF[[#This Row],[Total]])))))))))) -> 0 | L26: =IF(NDF[[#This Row],[Remboursement Calculé]]="","",IF(ISNA(INDEX(Mapping_Comptable[Libellé comptable],MATCH(CONCATENATE(NDF[[#This Row],[Evénement]],"/",NDF[[#This Row],[Type de dépense]]),Mapping_Comptable[Column1],0),0)),"en attente",IF(AND(NDF[[#This Row],[Type de dépense]]="Repas",OR(NDF[[#This Row],[Déjeuner/Dîner]]="",NDF[[#This Row],[Nb de pers]]="")),"",INDEX(Mapping_Comptable[Compte Comptable],MATCH(CONCATENATE(NDF[[#This Row],[Evénement]],"/",NDF[[#This Row],[Type de dépense]]),Mapping_Comptable[Column1],0),0)))) -> en attente | M26: =IF(NDF[[#This Row],[Remboursement Calculé]]="","en attente",IF(ISNA(INDEX(Mapping_Comptable[Libellé comptable],MATCH(CONCATENATE(NDF[[#This Row],[Evénement]],"/",NDF[[#This Row],[Type de dépense]]),Mapping_Comptable[Column1],0),0)),"en attente",IF(AND(NDF[[#This Row],[Type de dépense]]="Repas",OR(NDF[[#This Row],[Déjeuner/Dîner]]="",NDF[[#This Row],[Nb de pers]]="")),"",INDEX(Mapping_Comptable[Libellé comptable],MATCH(CONCATENATE(NDF[[#This Row],[Evénement]],"/",NDF[[#This Row],[Type de dépense]]),Mapping_Comptable[Column1],0),0)))) -> en attente | N26: =IF(B26="","",VLOOKUP(B26,Paramétrage!$E$2:$F$12,2,FALSE)) | O26: =IF(AND(NDF[[#This Row],[Ecole/Prog/Dépt]]="",NDF[[#This Row],[Ville]]=""),$B$6&$B$7,IF(AND(NDF[[#This Row],[Ecole/Prog/Dépt]]="",NDF[[#This Row],[Ville]]<>""),$B$6&NDF[[#This Row],[Ville]],IF(AND(NDF[[#This Row],[Ecole/Prog/Dépt]]<>"",NDF[[#This Row],[Ville]]=""),NDF[[#This Row],[Ecole/Prog/Dépt]]&$B$7,IF(AND(NDF[[#This Row],[Ecole/Prog/Dépt]]<>"",NDF[[#This Row],[Ville]]<>""),NDF[[#This Row],[Ecole/Prog/Dépt]]&NDF[[#This Row],[Ville]],"")))) -> EPITECH ITPARIS et RP | P26: =VLOOKUP(NDF[[#This Row],[Colonne1]],Paramétrage!$L$73:$M$223,2,FALSE) -> 0068 - IT PARIS | Q26: Montant NDF | R26: =HLOOKUP(NDF[[#This Row],[Evénement]],Paramétrage!$L$1:$P$2,2,0) -> #N/A | S26: =IF(AND(NDF[[#This Row],[Remboursement Calculé]]="",NDF[[#This Row],[Libellé de compte]]="en attente",NDF[[#This Row],[Type de dépense]]="Véhicule Personnel (trajet en Km Ecole/Salon)"),"Trajet ! Veuillez renseigner la puissance Fiscale de votre véhicule",IF(AND(NDF[[#This Row],[Evénement]]="Autre",NDF[[#This Row],[Type de dépense]]="Autre"),"En attente affectation par le comptable, renseigner un commentaire",IF(AND(NDF[[#This Row],[Remboursement Calculé]]>0,NDF[[#This Row],[Libellé de compte]]="en attente"),"Attention Evénement et Type de Dépense INCOMPATIBLES",IF(AND(NDF[[#This Row],[Type de dépense]]="Repas",OR(NDF[[#This Row],[Déjeuner/Dîner]]="",NDF[[#This Row],[Nb de pers]]="")),"Attention type de Dépense 'Repas' renseignez aussi le Type de Repas et/ou le nb de pers",IF(AND($B$7="",NDF[[#This Row],[Ville]]=""),"Ville non renseignée",IF(AND($B$6="",NDF[[#This Row],[Ecole/Prog/Dépt]]=""),"Ecole/Prog/Dépt non renseignés",""))))))
A27: 11 | K27: =IF(AND(NDF[[#This Row],[Type de dépense]]="Repas",NDF[[#This Row],[Déjeuner/Dîner]]="Dîner",Limit_Diner=0),NDF[[#This Row],[Total]],IF(AND(NDF[[#This Row],[Type de dépense]]="Repas",NDF[[#This Row],[Déjeuner/Dîner]]="Déjeuner",Limit_dej=0),NDF[[#This Row],[Total]],IF(AND(NDF[[#This Row],[Type de dépense]]="Hébergement",Hotel=0),NDF[[#This Row],[Total]],IF(AND(NDF[[#This Row],[Type de dépense]]="Hébergement",NDF[[#This Row],[Total]]>Hotel),Hotel,IF(AND(NDF[[#This Row],[Type de dépense]]="Véhicule Personnel (trajet en Km Ecole/Salon)",Puissance_Fiscale=""),"",IF(AND(NDF[[#This Row],[Type de dépense]]="Repas",NDF[[#This Row],[Déjeuner/Dîner]]<>0,NDF[[#This Row],[Nb de pers]]=""),"",IF(AND(NDF[[#This Row],[Type de dépense]]="Repas",NDF[[#This Row],[Déjeuner/Dîner]]="Déjeuner"),IF(NDF[[#This Row],[Total]]/NDF[[#This Row],[Nb de pers]]<(Limit_dej+0.01),NDF[[#This Row],[Total]],NDF[[#This Row],[Nb de pers]]*Limit_dej),IF(AND(NDF[[#This Row],[Type de dépense]]="Repas",NDF[[#This Row],[Déjeuner/Dîner]]="Dîner"),IF(NDF[[#This Row],[Total]]/NDF[[#This Row],[Nb de pers]]<Limit_Diner+0.01,NDF[[#This Row],[Total]],NDF[[#This Row],[Nb de pers]]*Limit_Diner),IF(NDF[[#This Row],[Type de dépense]]="Véhicule Personnel (trajet en Km Ecole/Salon)",NDF[[#This Row],[Total]]*Coeff_Fiscal,IF(AND(NDF[[#This Row],[Type de dépense]]="Repas",OR(NDF[[#This Row],[Déjeuner/Dîner]]="",NDF[[#This Row],[Nb de pers]]="")),"",NDF[[#This Row],[Total]])))))))))) -> 0 | L27: =IF(NDF[[#This Row],[Remboursement Calculé]]="","",IF(ISNA(INDEX(Mapping_Comptable[Libellé comptable],MATCH(CONCATENATE(NDF[[#This Row],[Evénement]],"/",NDF[[#This Row],[Type de dépense]]),Mapping_Comptable[Column1],0),0)),"en attente",IF(AND(NDF[[#This Row],[Type de dépense]]="Repas",OR(NDF[[#This Row],[Déjeuner/Dîner]]="",NDF[[#This Row],[Nb de pers]]="")),"",INDEX(Mapping_Comptable[Compte Comptable],MATCH(CONCATENATE(NDF[[#This Row],[Evénement]],"/",NDF[[#This Row],[Type de dépense]]),Mapping_Comptable[Column1],0),0)))) -> en attente | M27: =IF(NDF[[#This Row],[Remboursement Calculé]]="","en attente",IF(ISNA(INDEX(Mapping_Comptable[Libellé comptable],MATCH(CONCATENATE(NDF[[#This Row],[Evénement]],"/",NDF[[#This Row],[Type de dépense]]),Mapping_Comptable[Column1],0),0)),"en attente",IF(AND(NDF[[#This Row],[Type de dépense]]="Repas",OR(NDF[[#This Row],[Déjeuner/Dîner]]="",NDF[[#This Row],[Nb de pers]]="")),"",INDEX(Mapping_Comptable[Libellé comptable],MATCH(CONCATENATE(NDF[[#This Row],[Evénement]],"/",NDF[[#This Row],[Type de dépense]]),Mapping_Comptable[Column1],0),0)))) -> en attente | N27: =IF(B27="","",VLOOKUP(B27,Paramétrage!$E$2:$F$12,2,FALSE)) | O27: =IF(AND(NDF[[#This Row],[Ecole/Prog/Dépt]]="",NDF[[#This Row],[Ville]]=""),$B$6&$B$7,IF(AND(NDF[[#This Row],[Ecole/Prog/Dépt]]="",NDF[[#This Row],[Ville]]<>""),$B$6&NDF[[#This Row],[Ville]],IF(AND(NDF[[#This Row],[Ecole/Prog/Dépt]]<>"",NDF[[#This Row],[Ville]]=""),NDF[[#This Row],[Ecole/Prog/Dépt]]&$B$7,IF(AND(NDF[[#This Row],[Ecole/Prog/Dépt]]<>"",NDF[[#This Row],[Ville]]<>""),NDF[[#This Row],[Ecole/Prog/Dépt]]&NDF[[#This Row],[Ville]],"")))) -> EPITECH ITPARIS et RP | P27: =VLOOKUP(NDF[[#This Row],[Colonne1]],Paramétrage!$L$73:$M$223,2,FALSE) -> 0068 - IT PARIS | Q27: Montant NDF | R27: =HLOOKUP(NDF[[#This Row],[Evénement]],Paramétrage!$L$1:$P$2,2,0) -> #N/A | S27: =IF(AND(NDF[[#This Row],[Remboursement Calculé]]="",NDF[[#This Row],[Libellé de compte]]="en attente",NDF[[#This Row],[Type de dépense]]="Véhicule Personnel (trajet en Km Ecole/Salon)"),"Trajet ! Veuillez renseigner la puissance Fiscale de votre véhicule",IF(AND(NDF[[#This Row],[Evénement]]="Autre",NDF[[#This Row],[Type de dépense]]="Autre"),"En attente affectation par le comptable, renseigner un commentaire",IF(AND(NDF[[#This Row],[Remboursement Calculé]]>0,NDF[[#This Row],[Libellé de compte]]="en attente"),"Attention Evénement et Type de Dépense INCOMPATIBLES",IF(AND(NDF[[#This Row],[Type de dépense]]="Repas",OR(NDF[[#This Row],[Déjeuner/Dîner]]="",NDF[[#This Row],[Nb de pers]]="")),"Attention type de Dépense 'Repas' renseignez aussi le Type de Repas et/ou le nb de pers",IF(AND($B$7="",NDF[[#This Row],[Ville]]=""),"Ville non renseignée",IF(AND($B$6="",NDF[[#This Row],[Ecole/Prog/Dépt]]=""),"Ecole/Prog/Dépt non renseignés",""))))))
A28: 12 | K28: =IF(AND(NDF[[#This Row],[Type de dépense]]="Repas",NDF[[#This Row],[Déjeuner/Dîner]]="Dîner",Limit_Diner=0),NDF[[#This Row],[Total]],IF(AND(NDF[[#This Row],[Type de dépense]]="Repas",NDF[[#This Row],[Déjeuner/Dîner]]="Déjeuner",Limit_dej=0),NDF[[#This Row],[Total]],IF(AND(NDF[[#This Row],[Type de dépense]]="Hébergement",Hotel=0),NDF[[#This Row],[Total]],IF(AND(NDF[[#This Row],[Type de dépense]]="Hébergement",NDF[[#This Row],[Total]]>Hotel),Hotel,IF(AND(NDF[[#This Row],[Type de dépense]]="Véhicule Personnel (trajet en Km Ecole/Salon)",Puissance_Fiscale=""),"",IF(AND(NDF[[#This Row],[Type de dépense]]="Repas",NDF[[#This Row],[Déjeuner/Dîner]]<>0,NDF[[#This Row],[Nb de pers]]=""),"",IF(AND(NDF[[#This Row],[Type de dépense]]="Repas",NDF[[#This Row],[Déjeuner/Dîner]]="Déjeuner"),IF(NDF[[#This Row],[Total]]/NDF[[#This Row],[Nb de pers]]<(Limit_dej+0.01),NDF[[#This Row],[Total]],NDF[[#This Row],[Nb de pers]]*Limit_dej),IF(AND(NDF[[#This Row],[Type de dépense]]="Repas",NDF[[#This Row],[Déjeuner/Dîner]]="Dîner"),IF(NDF[[#This Row],[Total]]/NDF[[#This Row],[Nb de pers]]<Limit_Diner+0.01,NDF[[#This Row],[Total]],NDF[[#This Row],[Nb de pers]]*Limit_Diner),IF(NDF[[#This Row],[Type de dépense]]="Véhicule Personnel (trajet en Km Ecole/Salon)",NDF[[#This Row],[Total]]*Coeff_Fiscal,IF(AND(NDF[[#This Row],[Type de dépense]]="Repas",OR(NDF[[#This Row],[Déjeuner/Dîner]]="",NDF[[#This Row],[Nb de pers]]="")),"",NDF[[#This Row],[Total]])))))))))) -> 0 | L28: =IF(NDF[[#This Row],[Remboursement Calculé]]="","",IF(ISNA(INDEX(Mapping_Comptable[Libellé comptable],MATCH(CONCATENATE(NDF[[#This Row],[Evénement]],"/",NDF[[#This Row],[Type de dépense]]),Mapping_Comptable[Column1],0),0)),"en attente",IF(AND(NDF[[#This Row],[Type de dépense]]="Repas",OR(NDF[[#This Row],[Déjeuner/Dîner]]="",NDF[[#This Row],[Nb de pers]]="")),"",INDEX(Mapping_Comptable[Compte Comptable],MATCH(CONCATENATE(NDF[[#This Row],[Evénement]],"/",NDF[[#This Row],[Type de dépense]]),Mapping_Comptable[Column1],0),0)))) -> en attente | M28: =IF(NDF[[#This Row],[Remboursement Calculé]]="","en attente",IF(ISNA(INDEX(Mapping_Comptable[Libellé comptable],MATCH(CONCATENATE(NDF[[#This Row],[Evénement]],"/",NDF[[#This Row],[Type de dépense]]),Mapping_Comptable[Column1],0),0)),"en attente",IF(AND(NDF[[#This Row],[Type de dépense]]="Repas",OR(NDF[[#This Row],[Déjeuner/Dîner]]="",NDF[[#This Row],[Nb de pers]]="")),"",INDEX(Mapping_Comptable[Libellé comptable],MATCH(CONCATENATE(NDF[[#This Row],[Evénement]],"/",NDF[[#This Row],[Type de dépense]]),Mapping_Comptable[Column1],0),0)))) -> en attente | N28: =IF(B28="","",VLOOKUP(B28,Paramétrage!$E$2:$F$12,2,FALSE)) | O28: =IF(AND(NDF[[#This Row],[Ecole/Prog/Dépt]]="",NDF[[#This Row],[Ville]]=""),$B$6&$B$7,IF(AND(NDF[[#This Row],[Ecole/Prog/Dépt]]="",NDF[[#This Row],[Ville]]<>""),$B$6&NDF[[#This Row],[Ville]],IF(AND(NDF[[#This Row],[Ecole/Prog/Dépt]]<>"",NDF[[#This Row],[Ville]]=""),NDF[[#This Row],[Ecole/Prog/Dépt]]&$B$7,IF(AND(NDF[[#This Row],[Ecole/Prog/Dépt]]<>"",NDF[[#This Row],[Ville]]<>""),NDF[[#This Row],[Ecole/Prog/Dépt]]&NDF[[#This Row],[Ville]],"")))) -> EPITECH ITPARIS et RP | P28: =VLOOKUP(NDF[[#This Row],[Colonne1]],Paramétrage!$L$73:$M$223,2,FALSE) -> 0068 - IT PARIS | Q28: Montant NDF | R28: =HLOOKUP(NDF[[#This Row],[Evénement]],Paramétrage!$L$1:$P$2,2,0) -> #N/A | S28: =IF(AND(NDF[[#This Row],[Remboursement Calculé]]="",NDF[[#This Row],[Libellé de compte]]="en attente",NDF[[#This Row],[Type de dépense]]="Véhicule Personnel (trajet en Km Ecole/Salon)"),"Trajet ! Veuillez renseigner la puissance Fiscale de votre véhicule",IF(AND(NDF[[#This Row],[Evénement]]="Autre",NDF[[#This Row],[Type de dépense]]="Autre"),"En attente affectation par le comptable, renseigner un commentaire",IF(AND(NDF[[#This Row],[Remboursement Calculé]]>0,NDF[[#This Row],[Libellé de compte]]="en attente"),"Attention Evénement et Type de Dépense INCOMPATIBLES",IF(AND(NDF[[#This Row],[Type de dépense]]="Repas",OR(NDF[[#This Row],[Déjeuner/Dîner]]="",NDF[[#This Row],[Nb de pers]]="")),"Attention type de Dépense 'Repas' renseignez aussi le Type de Repas et/ou le nb de pers",IF(AND($B$7="",NDF[[#This Row],[Ville]]=""),"Ville non renseignée",IF(AND($B$6="",NDF[[#This Row],[Ecole/Prog/Dépt]]=""),"Ecole/Prog/Dépt non renseignés",""))))))
A29: 13 | K29: =IF(AND(NDF[[#This Row],[Type de dépense]]="Repas",NDF[[#This Row],[Déjeuner/Dîner]]="Dîner",Limit_Diner=0),NDF[[#This Row],[Total]],IF(AND(NDF[[#This Row],[Type de dépense]]="Repas",NDF[[#This Row],[Déjeuner/Dîner]]="Déjeuner",Limit_dej=0),NDF[[#This Row],[Total]],IF(AND(NDF[[#This Row],[Type de dépense]]="Hébergement",Hotel=0),NDF[[#This Row],[Total]],IF(AND(NDF[[#This Row],[Type de dépense]]="Hébergement",NDF[[#This Row],[Total]]>Hotel),Hotel,IF(AND(NDF[[#This Row],[Type de dépense]]="Véhicule Personnel (trajet en Km Ecole/Salon)",Puissance_Fiscale=""),"",IF(AND(NDF[[#This Row],[Type de dépense]]="Repas",NDF[[#This Row],[Déjeuner/Dîner]]<>0,NDF[[#This Row],[Nb de pers]]=""),"",IF(AND(NDF[[#This Row],[Type de dépense]]="Repas",NDF[[#This Row],[Déjeuner/Dîner]]="Déjeuner"),IF(NDF[[#This Row],[Total]]/NDF[[#This Row],[Nb de pers]]<(Limit_dej+0.01),NDF[[#This Row],[Total]],NDF[[#This Row],[Nb de pers]]*Limit_dej),IF(AND(NDF[[#This Row],[Type de dépense]]="Repas",NDF[[#This Row],[Déjeuner/Dîner]]="Dîner"),IF(NDF[[#This Row],[Total]]/NDF[[#This Row],[Nb de pers]]<Limit_Diner+0.01,NDF[[#This Row],[Total]],NDF[[#This Row],[Nb de pers]]*Limit_Diner),IF(NDF[[#This Row],[Type de dépense]]="Véhicule Personnel (trajet en Km Ecole/Salon)",NDF[[#This Row],[Total]]*Coeff_Fiscal,IF(AND(NDF[[#This Row],[Type de dépense]]="Repas",OR(NDF[[#This Row],[Déjeuner/Dîner]]="",NDF[[#This Row],[Nb de pers]]="")),"",NDF[[#This Row],[Total]])))))))))) -> 0 | L29: =IF(NDF[[#This Row],[Remboursement Calculé]]="","",IF(ISNA(INDEX(Mapping_Comptable[Libellé comptable],MATCH(CONCATENATE(NDF[[#This Row],[Evénement]],"/",NDF[[#This Row],[Type de dépense]]),Mapping_Comptable[Column1],0),0)),"en attente",IF(AND(NDF[[#This Row],[Type de dépense]]="Repas",OR(NDF[[#This Row],[Déjeuner/Dîner]]="",NDF[[#This Row],[Nb de pers]]="")),"",INDEX(Mapping_Comptable[Compte Comptable],MATCH(CONCATENATE(NDF[[#This Row],[Evénement]],"/",NDF[[#This Row],[Type de dépense]]),Mapping_Comptable[Column1],0),0)))) -> en attente | M29: =IF(NDF[[#This Row],[Remboursement Calculé]]="","en attente",IF(ISNA(INDEX(Mapping_Comptable[Libellé comptable],MATCH(CONCATENATE(NDF[[#This Row],[Evénement]],"/",NDF[[#This Row],[Type de dépense]]),Mapping_Comptable[Column1],0),0)),"en attente",IF(AND(NDF[[#This Row],[Type de dépense]]="Repas",OR(NDF[[#This Row],[Déjeuner/Dîner]]="",NDF[[#This Row],[Nb de pers]]="")),"",INDEX(Mapping_Comptable[Libellé comptable],MATCH(CONCATENATE(NDF[[#This Row],[Evénement]],"/",NDF[[#This Row],[Type de dépense]]),Mapping_Comptable[Column1],0),0)))) -> en attente | N29: =IF(B29="","",VLOOKUP(B29,Paramétrage!$E$2:$F$12,2,FALSE)) | O29: =IF(AND(NDF[[#This Row],[Ecole/Prog/Dépt]]="",NDF[[#This Row],[Ville]]=""),$B$6&$B$7,IF(AND(NDF[[#This Row],[Ecole/Prog/Dépt]]="",NDF[[#This Row],[Ville]]<>""),$B$6&NDF[[#This Row],[Ville]],IF(AND(NDF[[#This Row],[Ecole/Prog/Dépt]]<>"",NDF[[#This Row],[Ville]]=""),NDF[[#This Row],[Ecole/Prog/Dépt]]&$B$7,IF(AND(NDF[[#This Row],[Ecole/Prog/Dépt]]<>"",NDF[[#This Row],[Ville]]<>""),NDF[[#This Row],[Ecole/Prog/Dépt]]&NDF[[#This Row],[Ville]],"")))) -> EPITECH ITPARIS et RP | P29: =VLOOKUP(NDF[[#This Row],[Colonne1]],Paramétrage!$L$73:$M$223,2,FALSE) -> 0068 - IT PARIS | Q29: Montant NDF | R29: =HLOOKUP(NDF[[#This Row],[Evénement]],Paramétrage!$L$1:$P$2,2,0) -> #N/A | S29: =IF(AND(NDF[[#This Row],[Remboursement Calculé]]="",NDF[[#This Row],[Libellé de compte]]="en attente",NDF[[#This Row],[Type de dépense]]="Véhicule Personnel (trajet en Km Ecole/Salon)"),"Trajet ! Veuillez renseigner la puissance Fiscale de votre véhicule",IF(AND(NDF[[#This Row],[Evénement]]="Autre",NDF[[#This Row],[Type de dépense]]="Autre"),"En attente affectation par le comptable, renseigner un commentaire",IF(AND(NDF[[#This Row],[Remboursement Calculé]]>0,NDF[[#This Row],[Libellé de compte]]="en attente"),"Attention Evénement et Type de Dépense INCOMPATIBLES",IF(AND(NDF[[#This Row],[Type de dépense]]="Repas",OR(NDF[[#This Row],[Déjeuner/Dîner]]="",NDF[[#This Row],[Nb de pers]]="")),"Attention type de Dépense 'Repas' renseignez aussi le Type de Repas et/ou le nb de pers",IF(AND($B$7="",NDF[[#This Row],[Ville]]=""),"Ville non renseignée",IF(AND($B$6="",NDF[[#This Row],[Ecole/Prog/Dépt]]=""),"Ecole/Prog/Dépt non renseignés",""))))))
